
root - ERROR - Error with getting cleint of parsed user uuid
root - ERROR - Client matching query does not exist.
django.request - WARNING - Bad Request: /v0.5/store/operation/chat/
django.utils.autoreload - INFO - /Users/elliott/Dropbox/pROJECTS/web_Dev/storevictor/storevictor/store/views.py changed, reloading.
django.utils.autoreload - INFO - /Users/elliott/Dropbox/pROJECTS/web_Dev/storevictor/storevictor/store/views.py changed, reloading.
root - ERROR - Error with getting cleint of parsed user uuid
root - ERROR - Client matching query does not exist.
django.request - WARNING - Bad Request: /v0.5/store/operation/chat/
django.utils.autoreload - INFO - /Users/elliott/Dropbox/pROJECTS/web_Dev/storevictor/storevictor/store/views.py changed, reloading.
django.utils.autoreload - INFO - /Users/elliott/Dropbox/pROJECTS/web_Dev/storevictor/storevictor/store/views.py changed, reloading.
django.utils.autoreload - INFO - /Users/elliott/Dropbox/pROJECTS/web_Dev/storevictor/storevictor/store/views.py changed, reloading.
root - ERROR - Error with getting client of parsed user uuid
root - ERROR - Client matching query does not exist.
django.request - WARNING - Bad Request: /v0.5/store/operation/chat/
django.utils.autoreload - INFO - /Users/elliott/Dropbox/pROJECTS/web_Dev/storevictor/storevictor/store/views.py changed, reloading.
django.utils.autoreload - INFO - /Users/elliott/Dropbox/pROJECTS/web_Dev/storevictor/storevictor/store/views.py changed, reloading.
root - ERROR - Error with getting client of parsed user uuid
root - ERROR - Client matching query does not exist.
django.request - WARNING - Bad Request: /v0.5/store/operation/chat/
django.utils.autoreload - INFO - /Users/elliott/Dropbox/pROJECTS/web_Dev/storevictor/storevictor/store/views.py changed, reloading.
django.utils.autoreload - INFO - /Users/elliott/Dropbox/pROJECTS/web_Dev/storevictor/storevictor/store/views.py changed, reloading.
django.utils.autoreload - INFO - /Users/elliott/Dropbox/pROJECTS/web_Dev/storevictor/storevictor/store/views.py changed, reloading.
django.utils.autoreload - INFO - /Users/elliott/Dropbox/pROJECTS/web_Dev/storevictor/storevictor/utility/validators.py changed, reloading.
django.utils.autoreload - INFO - /Users/elliott/Dropbox/pROJECTS/web_Dev/storevictor/storevictor/store/models.py changed, reloading.
django.utils.autoreload - INFO - /Users/elliott/Dropbox/pROJECTS/web_Dev/storevictor/storevictor/store/models.py changed, reloading.
django.utils.autoreload - INFO - /Users/elliott/Dropbox/pROJECTS/web_Dev/storevictor/storevictor/store/models.py changed, reloading.
django.utils.autoreload - INFO - /Users/elliott/Dropbox/pROJECTS/web_Dev/storevictor/storevictor/store/models.py changed, reloading.
django.request - WARNING - Bad Request: /v0.5/store/operation/chat/
django.request - WARNING - Bad Request: /v0.5/store/operation/chat/
django.utils.autoreload - INFO - /Users/elliott/Dropbox/pROJECTS/web_Dev/storevictor/storevictor/store/models.py changed, reloading.
django.request - WARNING - Bad Request: /v0.5/store/operation/chat/
django.request - WARNING - Not Found: /v0.5/store/operations/conversation/
django.utils.autoreload - INFO - /Users/elliott/Dropbox/pROJECTS/web_Dev/storevictor/storevictor/store/urls.py changed, reloading.
django.utils.autoreload - INFO - /Users/elliott/Dropbox/pROJECTS/web_Dev/storevictor/storevictor/store/views.py changed, reloading.
django.utils.autoreload - INFO - /Users/elliott/Dropbox/pROJECTS/web_Dev/storevictor/storevictor/store/views.py changed, reloading.
django.utils.autoreload - INFO - /Users/elliott/Dropbox/pROJECTS/web_Dev/storevictor/storevictor/store/models.py changed, reloading.
django.utils.autoreload - INFO - /Users/elliott/Dropbox/pROJECTS/web_Dev/storevictor/storevictor/store/views.py changed, reloading.
django.utils.autoreload - INFO - /Users/elliott/Dropbox/pROJECTS/web_Dev/storevictor/storevictor/store/views.py changed, reloading.
django.utils.autoreload - INFO - /Users/elliott/Dropbox/pROJECTS/web_Dev/storevictor/storevictor/store/views.py changed, reloading.
django.utils.autoreload - INFO - /Users/elliott/Dropbox/pROJECTS/web_Dev/storevictor/storevictor/store/views.py changed, reloading.
django.utils.autoreload - INFO - /Users/elliott/Dropbox/pROJECTS/web_Dev/storevictor/storevictor/store/views.py changed, reloading.
django.utils.autoreload - INFO - /Users/elliott/Dropbox/pROJECTS/web_Dev/storevictor/storevictor/store/views.py changed, reloading.
django.utils.autoreload - INFO - /Users/elliott/Dropbox/pROJECTS/web_Dev/storevictor/storevictor/store/urls.py changed, reloading.
django.utils.autoreload - INFO - /Users/elliott/Dropbox/pROJECTS/web_Dev/storevictor/storevictor/store/urls.py changed, reloading.
django.request - WARNING - Bad Request: /v0.5/store/operations/chat/8a4a7537-66e8-4607-b498-3f895f860a9f/
django.request - WARNING - Bad Request: /v0.5/store/operations/chat/
django.utils.autoreload - INFO - /Users/elliott/Dropbox/pROJECTS/web_Dev/storevictor/storevictor/store/models.py changed, reloading.
django.request - ERROR - Internal Server Error: /v0.5/store/operations/chat/
Traceback (most recent call last):
  File "/Users/elliott/python_venv/store/lib/python3.9/site-packages/django/core/handlers/exception.py", line 47, in inner
    response = get_response(request)
  File "/Users/elliott/python_venv/store/lib/python3.9/site-packages/django/core/handlers/base.py", line 181, in _get_response
    response = wrapped_callback(request, *callback_args, **callback_kwargs)
  File "/Users/elliott/python_venv/store/lib/python3.9/site-packages/django/views/decorators/csrf.py", line 54, in wrapped_view
    return view_func(*args, **kwargs)
  File "/Users/elliott/python_venv/store/lib/python3.9/site-packages/django/views/generic/base.py", line 70, in view
    return self.dispatch(request, *args, **kwargs)
  File "/Users/elliott/python_venv/store/lib/python3.9/site-packages/rest_framework/views.py", line 509, in dispatch
    response = self.handle_exception(exc)
  File "/Users/elliott/python_venv/store/lib/python3.9/site-packages/rest_framework/views.py", line 469, in handle_exception
    self.raise_uncaught_exception(exc)
  File "/Users/elliott/python_venv/store/lib/python3.9/site-packages/rest_framework/views.py", line 480, in raise_uncaught_exception
    raise exc
  File "/Users/elliott/python_venv/store/lib/python3.9/site-packages/rest_framework/views.py", line 506, in dispatch
    response = handler(request, *args, **kwargs)
  File "/Users/elliott/Dropbox/pROJECTS/web_Dev/storevictor/storevictor/store/views.py", line 59, in post
    serializer.is_valid(raise_exception=True)
  File "/Users/elliott/python_venv/store/lib/python3.9/site-packages/rest_framework/serializers.py", line 220, in is_valid
    self._validated_data = self.run_validation(self.initial_data)
  File "/Users/elliott/python_venv/store/lib/python3.9/site-packages/rest_framework/serializers.py", line 419, in run_validation
    value = self.to_internal_value(data)
  File "/Users/elliott/python_venv/store/lib/python3.9/site-packages/rest_framework/serializers.py", line 476, in to_internal_value
    validated_value = field.run_validation(primitive_value)
  File "/Users/elliott/python_venv/store/lib/python3.9/site-packages/rest_framework/fields.py", line 799, in run_validation
    return super().run_validation(data)
  File "/Users/elliott/python_venv/store/lib/python3.9/site-packages/rest_framework/fields.py", line 569, in run_validation
    self.run_validators(value)
  File "/Users/elliott/python_venv/store/lib/python3.9/site-packages/rest_framework/fields.py", line 593, in run_validators
    validator(value)
  File "/Users/elliott/python_venv/store/lib/python3.9/site-packages/django/core/validators.py", line 48, in __call__
    regex_matches = self.regex.search(str(value))
  File "/Users/elliott/python_venv/store/lib/python3.9/site-packages/django/utils/functional.py", line 246, in inner
    self._setup()
  File "/Users/elliott/python_venv/store/lib/python3.9/site-packages/django/utils/functional.py", line 382, in _setup
    self._wrapped = self._setupfunc()
  File "/Users/elliott/python_venv/store/lib/python3.9/site-packages/django/utils/regex_helper.py", line 345, in _compile
    return re.compile(regex, flags)
  File "/usr/local/Cellar/python@3.9/3.9.7/Frameworks/Python.framework/Versions/3.9/lib/python3.9/re.py", line 252, in compile
    return _compile(pattern, flags)
  File "/usr/local/Cellar/python@3.9/3.9.7/Frameworks/Python.framework/Versions/3.9/lib/python3.9/re.py", line 304, in _compile
    p = sre_compile.compile(pattern, flags)
  File "/usr/local/Cellar/python@3.9/3.9.7/Frameworks/Python.framework/Versions/3.9/lib/python3.9/sre_compile.py", line 764, in compile
    p = sre_parse.parse(p, flags)
  File "/usr/local/Cellar/python@3.9/3.9.7/Frameworks/Python.framework/Versions/3.9/lib/python3.9/sre_parse.py", line 948, in parse
    p = _parse_sub(source, state, flags & SRE_FLAG_VERBOSE, 0)
  File "/usr/local/Cellar/python@3.9/3.9.7/Frameworks/Python.framework/Versions/3.9/lib/python3.9/sre_parse.py", line 443, in _parse_sub
    itemsappend(_parse(source, state, verbose, nested + 1,
  File "/usr/local/Cellar/python@3.9/3.9.7/Frameworks/Python.framework/Versions/3.9/lib/python3.9/sre_parse.py", line 668, in _parse
    raise source.error("nothing to repeat",
re.error: nothing to repeat at position 0
django.utils.autoreload - INFO - /Users/elliott/Dropbox/pROJECTS/web_Dev/storevictor/storevictor/store/models.py changed, reloading.
django.utils.autoreload - INFO - /Users/elliott/Dropbox/pROJECTS/web_Dev/storevictor/storevictor/store/models.py changed, reloading.
django.request - WARNING - Bad Request: /v0.5/store/operations/chat/
django.utils.autoreload - INFO - /Users/elliott/Dropbox/pROJECTS/web_Dev/storevictor/storevictor/store/models.py changed, reloading.
django.request - WARNING - Bad Request: /v0.5/store/operations/chat/
django.request - WARNING - Bad Request: /v0.5/store/operations/chat/
django.utils.autoreload - INFO - /Users/elliott/Dropbox/pROJECTS/web_Dev/storevictor/storevictor/store/models.py changed, reloading.
django.utils.autoreload - INFO - /Users/elliott/Dropbox/pROJECTS/web_Dev/storevictor/storevictor/store/models.py changed, reloading.
django.request - ERROR - Internal Server Error: /v0.5/store/operations/chat/8a4a7537-66e8-4607-b498-3f895f860a9f/
Traceback (most recent call last):
  File "/Users/elliott/python_venv/store/lib/python3.9/site-packages/django/core/handlers/exception.py", line 47, in inner
    response = get_response(request)
  File "/Users/elliott/python_venv/store/lib/python3.9/site-packages/django/core/handlers/base.py", line 181, in _get_response
    response = wrapped_callback(request, *callback_args, **callback_kwargs)
  File "/Users/elliott/python_venv/store/lib/python3.9/site-packages/django/views/decorators/csrf.py", line 54, in wrapped_view
    return view_func(*args, **kwargs)
  File "/Users/elliott/python_venv/store/lib/python3.9/site-packages/django/views/generic/base.py", line 70, in view
    return self.dispatch(request, *args, **kwargs)
  File "/Users/elliott/python_venv/store/lib/python3.9/site-packages/rest_framework/views.py", line 509, in dispatch
    response = self.handle_exception(exc)
  File "/Users/elliott/python_venv/store/lib/python3.9/site-packages/rest_framework/views.py", line 469, in handle_exception
    self.raise_uncaught_exception(exc)
  File "/Users/elliott/python_venv/store/lib/python3.9/site-packages/rest_framework/views.py", line 480, in raise_uncaught_exception
    raise exc
  File "/Users/elliott/python_venv/store/lib/python3.9/site-packages/rest_framework/views.py", line 506, in dispatch
    response = handler(request, *args, **kwargs)
  File "/Users/elliott/Dropbox/pROJECTS/web_Dev/storevictor/storevictor/store/views.py", line 35, in put
    if serializer.is_valid():
  File "/Users/elliott/python_venv/store/lib/python3.9/site-packages/rest_framework/serializers.py", line 220, in is_valid
    self._validated_data = self.run_validation(self.initial_data)
  File "/Users/elliott/python_venv/store/lib/python3.9/site-packages/rest_framework/serializers.py", line 419, in run_validation
    value = self.to_internal_value(data)
  File "/Users/elliott/python_venv/store/lib/python3.9/site-packages/rest_framework/serializers.py", line 476, in to_internal_value
    validated_value = field.run_validation(primitive_value)
  File "/Users/elliott/python_venv/store/lib/python3.9/site-packages/rest_framework/fields.py", line 799, in run_validation
    return super().run_validation(data)
  File "/Users/elliott/python_venv/store/lib/python3.9/site-packages/rest_framework/fields.py", line 569, in run_validation
    self.run_validators(value)
  File "/Users/elliott/python_venv/store/lib/python3.9/site-packages/rest_framework/fields.py", line 593, in run_validators
    validator(value)
  File "/Users/elliott/python_venv/store/lib/python3.9/site-packages/django/core/validators.py", line 48, in __call__
    regex_matches = self.regex.search(str(value))
  File "/Users/elliott/python_venv/store/lib/python3.9/site-packages/django/utils/functional.py", line 246, in inner
    self._setup()
  File "/Users/elliott/python_venv/store/lib/python3.9/site-packages/django/utils/functional.py", line 382, in _setup
    self._wrapped = self._setupfunc()
  File "/Users/elliott/python_venv/store/lib/python3.9/site-packages/django/utils/regex_helper.py", line 345, in _compile
    return re.compile(regex, flags)
  File "/usr/local/Cellar/python@3.9/3.9.7/Frameworks/Python.framework/Versions/3.9/lib/python3.9/re.py", line 252, in compile
    return _compile(pattern, flags)
  File "/usr/local/Cellar/python@3.9/3.9.7/Frameworks/Python.framework/Versions/3.9/lib/python3.9/re.py", line 304, in _compile
    p = sre_compile.compile(pattern, flags)
  File "/usr/local/Cellar/python@3.9/3.9.7/Frameworks/Python.framework/Versions/3.9/lib/python3.9/sre_compile.py", line 764, in compile
    p = sre_parse.parse(p, flags)
  File "/usr/local/Cellar/python@3.9/3.9.7/Frameworks/Python.framework/Versions/3.9/lib/python3.9/sre_parse.py", line 948, in parse
    p = _parse_sub(source, state, flags & SRE_FLAG_VERBOSE, 0)
  File "/usr/local/Cellar/python@3.9/3.9.7/Frameworks/Python.framework/Versions/3.9/lib/python3.9/sre_parse.py", line 443, in _parse_sub
    itemsappend(_parse(source, state, verbose, nested + 1,
  File "/usr/local/Cellar/python@3.9/3.9.7/Frameworks/Python.framework/Versions/3.9/lib/python3.9/sre_parse.py", line 668, in _parse
    raise source.error("nothing to repeat",
re.error: nothing to repeat at position 0
django.request - ERROR - Internal Server Error: /v0.5/store/operations/chat/8a4a7537-66e8-4607-b498-3f895f860a9f/
Traceback (most recent call last):
  File "/Users/elliott/python_venv/store/lib/python3.9/site-packages/django/core/handlers/exception.py", line 47, in inner
    response = get_response(request)
  File "/Users/elliott/python_venv/store/lib/python3.9/site-packages/django/core/handlers/base.py", line 181, in _get_response
    response = wrapped_callback(request, *callback_args, **callback_kwargs)
  File "/Users/elliott/python_venv/store/lib/python3.9/site-packages/django/views/decorators/csrf.py", line 54, in wrapped_view
    return view_func(*args, **kwargs)
  File "/Users/elliott/python_venv/store/lib/python3.9/site-packages/django/views/generic/base.py", line 70, in view
    return self.dispatch(request, *args, **kwargs)
  File "/Users/elliott/python_venv/store/lib/python3.9/site-packages/rest_framework/views.py", line 509, in dispatch
    response = self.handle_exception(exc)
  File "/Users/elliott/python_venv/store/lib/python3.9/site-packages/rest_framework/views.py", line 469, in handle_exception
    self.raise_uncaught_exception(exc)
  File "/Users/elliott/python_venv/store/lib/python3.9/site-packages/rest_framework/views.py", line 480, in raise_uncaught_exception
    raise exc
  File "/Users/elliott/python_venv/store/lib/python3.9/site-packages/rest_framework/views.py", line 506, in dispatch
    response = handler(request, *args, **kwargs)
  File "/Users/elliott/Dropbox/pROJECTS/web_Dev/storevictor/storevictor/store/views.py", line 35, in put
    if serializer.is_valid():
  File "/Users/elliott/python_venv/store/lib/python3.9/site-packages/rest_framework/serializers.py", line 220, in is_valid
    self._validated_data = self.run_validation(self.initial_data)
  File "/Users/elliott/python_venv/store/lib/python3.9/site-packages/rest_framework/serializers.py", line 419, in run_validation
    value = self.to_internal_value(data)
  File "/Users/elliott/python_venv/store/lib/python3.9/site-packages/rest_framework/serializers.py", line 476, in to_internal_value
    validated_value = field.run_validation(primitive_value)
  File "/Users/elliott/python_venv/store/lib/python3.9/site-packages/rest_framework/fields.py", line 799, in run_validation
    return super().run_validation(data)
  File "/Users/elliott/python_venv/store/lib/python3.9/site-packages/rest_framework/fields.py", line 569, in run_validation
    self.run_validators(value)
  File "/Users/elliott/python_venv/store/lib/python3.9/site-packages/rest_framework/fields.py", line 593, in run_validators
    validator(value)
  File "/Users/elliott/python_venv/store/lib/python3.9/site-packages/django/core/validators.py", line 48, in __call__
    regex_matches = self.regex.search(str(value))
  File "/Users/elliott/python_venv/store/lib/python3.9/site-packages/django/utils/functional.py", line 246, in inner
    self._setup()
  File "/Users/elliott/python_venv/store/lib/python3.9/site-packages/django/utils/functional.py", line 382, in _setup
    self._wrapped = self._setupfunc()
  File "/Users/elliott/python_venv/store/lib/python3.9/site-packages/django/utils/regex_helper.py", line 345, in _compile
    return re.compile(regex, flags)
  File "/usr/local/Cellar/python@3.9/3.9.7/Frameworks/Python.framework/Versions/3.9/lib/python3.9/re.py", line 252, in compile
    return _compile(pattern, flags)
  File "/usr/local/Cellar/python@3.9/3.9.7/Frameworks/Python.framework/Versions/3.9/lib/python3.9/re.py", line 304, in _compile
    p = sre_compile.compile(pattern, flags)
  File "/usr/local/Cellar/python@3.9/3.9.7/Frameworks/Python.framework/Versions/3.9/lib/python3.9/sre_compile.py", line 764, in compile
    p = sre_parse.parse(p, flags)
  File "/usr/local/Cellar/python@3.9/3.9.7/Frameworks/Python.framework/Versions/3.9/lib/python3.9/sre_parse.py", line 948, in parse
    p = _parse_sub(source, state, flags & SRE_FLAG_VERBOSE, 0)
  File "/usr/local/Cellar/python@3.9/3.9.7/Frameworks/Python.framework/Versions/3.9/lib/python3.9/sre_parse.py", line 443, in _parse_sub
    itemsappend(_parse(source, state, verbose, nested + 1,
  File "/usr/local/Cellar/python@3.9/3.9.7/Frameworks/Python.framework/Versions/3.9/lib/python3.9/sre_parse.py", line 668, in _parse
    raise source.error("nothing to repeat",
re.error: nothing to repeat at position 0
django.utils.autoreload - INFO - /Users/elliott/Dropbox/pROJECTS/web_Dev/storevictor/storevictor/store/models.py changed, reloading.
django.utils.autoreload - INFO - /Users/elliott/Dropbox/pROJECTS/web_Dev/storevictor/storevictor/store/models.py changed, reloading.
django.request - ERROR - Internal Server Error: /v0.5/store/operations/chat/8a4a7537-66e8-4607-b498-3f895f860a9f/
Traceback (most recent call last):
  File "/Users/elliott/python_venv/store/lib/python3.9/site-packages/django/core/handlers/exception.py", line 47, in inner
    response = get_response(request)
  File "/Users/elliott/python_venv/store/lib/python3.9/site-packages/django/core/handlers/base.py", line 181, in _get_response
    response = wrapped_callback(request, *callback_args, **callback_kwargs)
  File "/Users/elliott/python_venv/store/lib/python3.9/site-packages/django/views/decorators/csrf.py", line 54, in wrapped_view
    return view_func(*args, **kwargs)
  File "/Users/elliott/python_venv/store/lib/python3.9/site-packages/django/views/generic/base.py", line 70, in view
    return self.dispatch(request, *args, **kwargs)
  File "/Users/elliott/python_venv/store/lib/python3.9/site-packages/rest_framework/views.py", line 509, in dispatch
    response = self.handle_exception(exc)
  File "/Users/elliott/python_venv/store/lib/python3.9/site-packages/rest_framework/views.py", line 469, in handle_exception
    self.raise_uncaught_exception(exc)
  File "/Users/elliott/python_venv/store/lib/python3.9/site-packages/rest_framework/views.py", line 480, in raise_uncaught_exception
    raise exc
  File "/Users/elliott/python_venv/store/lib/python3.9/site-packages/rest_framework/views.py", line 506, in dispatch
    response = handler(request, *args, **kwargs)
  File "/Users/elliott/Dropbox/pROJECTS/web_Dev/storevictor/storevictor/store/views.py", line 35, in put
    if serializer.is_valid():
  File "/Users/elliott/python_venv/store/lib/python3.9/site-packages/rest_framework/serializers.py", line 220, in is_valid
    self._validated_data = self.run_validation(self.initial_data)
  File "/Users/elliott/python_venv/store/lib/python3.9/site-packages/rest_framework/serializers.py", line 419, in run_validation
    value = self.to_internal_value(data)
  File "/Users/elliott/python_venv/store/lib/python3.9/site-packages/rest_framework/serializers.py", line 476, in to_internal_value
    validated_value = field.run_validation(primitive_value)
  File "/Users/elliott/python_venv/store/lib/python3.9/site-packages/rest_framework/fields.py", line 799, in run_validation
    return super().run_validation(data)
  File "/Users/elliott/python_venv/store/lib/python3.9/site-packages/rest_framework/fields.py", line 569, in run_validation
    self.run_validators(value)
  File "/Users/elliott/python_venv/store/lib/python3.9/site-packages/rest_framework/fields.py", line 593, in run_validators
    validator(value)
  File "/Users/elliott/python_venv/store/lib/python3.9/site-packages/django/core/validators.py", line 48, in __call__
    regex_matches = self.regex.search(str(value))
  File "/Users/elliott/python_venv/store/lib/python3.9/site-packages/django/utils/functional.py", line 246, in inner
    self._setup()
  File "/Users/elliott/python_venv/store/lib/python3.9/site-packages/django/utils/functional.py", line 382, in _setup
    self._wrapped = self._setupfunc()
  File "/Users/elliott/python_venv/store/lib/python3.9/site-packages/django/utils/regex_helper.py", line 345, in _compile
    return re.compile(regex, flags)
  File "/usr/local/Cellar/python@3.9/3.9.7/Frameworks/Python.framework/Versions/3.9/lib/python3.9/re.py", line 252, in compile
    return _compile(pattern, flags)
  File "/usr/local/Cellar/python@3.9/3.9.7/Frameworks/Python.framework/Versions/3.9/lib/python3.9/re.py", line 304, in _compile
    p = sre_compile.compile(pattern, flags)
  File "/usr/local/Cellar/python@3.9/3.9.7/Frameworks/Python.framework/Versions/3.9/lib/python3.9/sre_compile.py", line 764, in compile
    p = sre_parse.parse(p, flags)
  File "/usr/local/Cellar/python@3.9/3.9.7/Frameworks/Python.framework/Versions/3.9/lib/python3.9/sre_parse.py", line 948, in parse
    p = _parse_sub(source, state, flags & SRE_FLAG_VERBOSE, 0)
  File "/usr/local/Cellar/python@3.9/3.9.7/Frameworks/Python.framework/Versions/3.9/lib/python3.9/sre_parse.py", line 443, in _parse_sub
    itemsappend(_parse(source, state, verbose, nested + 1,
  File "/usr/local/Cellar/python@3.9/3.9.7/Frameworks/Python.framework/Versions/3.9/lib/python3.9/sre_parse.py", line 598, in _parse
    raise source.error(msg, len(this) + 1 + len(that))
re.error: bad character range _-\/ at position 21
django.utils.autoreload - INFO - /Users/elliott/Dropbox/pROJECTS/web_Dev/storevictor/storevictor/store/models.py changed, reloading.
django.utils.autoreload - INFO - /Users/elliott/Dropbox/pROJECTS/web_Dev/storevictor/storevictor/store/models.py changed, reloading.
django.utils.autoreload - INFO - /Users/elliott/Dropbox/pROJECTS/web_Dev/storevictor/storevictor/store/models.py changed, reloading.
django.utils.autoreload - INFO - /Users/elliott/Dropbox/pROJECTS/web_Dev/storevictor/storevictor/store/views.py changed, reloading.
django.utils.autoreload - INFO - /Users/elliott/Dropbox/pROJECTS/web_Dev/storevictor/storevictor/store/views.py changed, reloading.
django.utils.autoreload - INFO - /Users/elliott/Dropbox/pROJECTS/web_Dev/storevictor/storevictor/store/views.py changed, reloading.
django.utils.autoreload - INFO - /Users/elliott/Dropbox/pROJECTS/web_Dev/storevictor/storevictor/store/models.py changed, reloading.
django.utils.autoreload - INFO - /Users/elliott/Dropbox/pROJECTS/web_Dev/storevictor/storevictor/store/models.py changed, reloading.
django.utils.autoreload - INFO - /Users/elliott/Dropbox/pROJECTS/web_Dev/storevictor/storevictor/store/models.py changed, reloading.
django.utils.autoreload - INFO - /Users/elliott/Dropbox/pROJECTS/web_Dev/storevictor/storevictor/store/models.py changed, reloading.
django.utils.autoreload - INFO - /Users/elliott/Dropbox/pROJECTS/web_Dev/storevictor/storevictor/store/models.py changed, reloading.
django.utils.autoreload - INFO - /Users/elliott/Dropbox/pROJECTS/web_Dev/storevictor/storevictor/store/models.py changed, reloading.
django.utils.autoreload - INFO - /Users/elliott/Dropbox/pROJECTS/web_Dev/storevictor/storevictor/store/models.py changed, reloading.
django.utils.autoreload - INFO - /Users/elliott/Dropbox/pROJECTS/web_Dev/storevictor/storevictor/store/models.py changed, reloading.
django.utils.autoreload - INFO - /Users/elliott/Dropbox/pROJECTS/web_Dev/storevictor/storevictor/store/models.py changed, reloading.
django.utils.autoreload - INFO - /Users/elliott/Dropbox/pROJECTS/web_Dev/storevictor/storevictor/store/views.py changed, reloading.
django.utils.autoreload - INFO - /Users/elliott/Dropbox/pROJECTS/web_Dev/storevictor/storevictor/store/serializers.py changed, reloading.
django.utils.autoreload - INFO - /Users/elliott/Dropbox/pROJECTS/web_Dev/storevictor/storevictor/store/models.py changed, reloading.
django.utils.autoreload - INFO - /Users/elliott/Dropbox/pROJECTS/web_Dev/storevictor/storevictor/store/serializers.py changed, reloading.
django.utils.autoreload - INFO - /Users/elliott/Dropbox/pROJECTS/web_Dev/storevictor/storevictor/store/views.py changed, reloading.
django.utils.autoreload - INFO - /Users/elliott/Dropbox/pROJECTS/web_Dev/storevictor/storevictor/store/views.py changed, reloading.
django.utils.autoreload - INFO - /Users/elliott/Dropbox/pROJECTS/web_Dev/storevictor/storevictor/store/urls.py changed, reloading.
django.utils.autoreload - INFO - /Users/elliott/Dropbox/pROJECTS/web_Dev/storevictor/storevictor/store/urls.py changed, reloading.
django.utils.autoreload - INFO - /Users/elliott/Dropbox/pROJECTS/web_Dev/storevictor/storevictor/store/serializers.py changed, reloading.
django.request - WARNING - Method Not Allowed: /v0.5/store/operations/chat/respond/
django.utils.autoreload - INFO - /Users/elliott/Dropbox/pROJECTS/web_Dev/storevictor/storevictor/store/urls.py changed, reloading.
django.utils.autoreload - INFO - /Users/elliott/Dropbox/pROJECTS/web_Dev/storevictor/storevictor/store/urls.py changed, reloading.
django.request - WARNING - Method Not Allowed: /v0.5/store/operations/chat/respond/
django.utils.autoreload - INFO - /Users/elliott/Dropbox/pROJECTS/web_Dev/storevictor/storevictor/store/urls.py changed, reloading.
django.request - WARNING - Bad Request: /v0.5/store/operations/chat/respond/
django.request - ERROR - Internal Server Error: /v0.5/store/operations/chat/respond/
Traceback (most recent call last):
  File "/Users/elliott/python_venv/store/lib/python3.9/site-packages/django/core/handlers/exception.py", line 47, in inner
    response = get_response(request)
  File "/Users/elliott/python_venv/store/lib/python3.9/site-packages/django/core/handlers/base.py", line 181, in _get_response
    response = wrapped_callback(request, *callback_args, **callback_kwargs)
  File "/Users/elliott/python_venv/store/lib/python3.9/site-packages/django/views/decorators/csrf.py", line 54, in wrapped_view
    return view_func(*args, **kwargs)
  File "/Users/elliott/python_venv/store/lib/python3.9/site-packages/django/views/generic/base.py", line 70, in view
    return self.dispatch(request, *args, **kwargs)
  File "/Users/elliott/python_venv/store/lib/python3.9/site-packages/rest_framework/views.py", line 509, in dispatch
    response = self.handle_exception(exc)
  File "/Users/elliott/python_venv/store/lib/python3.9/site-packages/rest_framework/views.py", line 469, in handle_exception
    self.raise_uncaught_exception(exc)
  File "/Users/elliott/python_venv/store/lib/python3.9/site-packages/rest_framework/views.py", line 480, in raise_uncaught_exception
    raise exc
  File "/Users/elliott/python_venv/store/lib/python3.9/site-packages/rest_framework/views.py", line 506, in dispatch
    response = handler(request, *args, **kwargs)
  File "/Users/elliott/Dropbox/pROJECTS/web_Dev/storevictor/storevictor/store/views.py", line 26, in post
    user = serializer.validated_data["user"]
KeyError: 'user'
django.utils.autoreload - INFO - /Users/elliott/Dropbox/pROJECTS/web_Dev/storevictor/storevictor/store/views.py changed, reloading.
django.utils.autoreload - INFO - /Users/elliott/Dropbox/pROJECTS/web_Dev/storevictor/storevictor/store/views.py changed, reloading.
django.utils.autoreload - INFO - /Users/elliott/Dropbox/pROJECTS/web_Dev/storevictor/storevictor/store/views.py changed, reloading.
django.utils.autoreload - INFO - /Users/elliott/Dropbox/pROJECTS/web_Dev/storevictor/storevictor/store/views.py changed, reloading.
django.utils.autoreload - INFO - /Users/elliott/Dropbox/pROJECTS/web_Dev/storevictor/storevictor/store/views.py changed, reloading.
django.utils.autoreload - INFO - /Users/elliott/Dropbox/pROJECTS/web_Dev/storevictor/storevictor/store/views.py changed, reloading.
django.utils.autoreload - INFO - /Users/elliott/Dropbox/pROJECTS/web_Dev/storevictor/storevictor/store/views.py changed, reloading.
django.utils.autoreload - INFO - /Users/elliott/Dropbox/pROJECTS/web_Dev/storevictor/storevictor/store/views.py changed, reloading.
django.utils.autoreload - INFO - /Users/elliott/Dropbox/pROJECTS/web_Dev/storevictor/storevictor/store/views.py changed, reloading.
django.utils.autoreload - INFO - /Users/elliott/Dropbox/pROJECTS/web_Dev/storevictor/storevictor/store/views.py changed, reloading.
django.utils.autoreload - INFO - /Users/elliott/Dropbox/pROJECTS/web_Dev/storevictor/storevictor/storevictor/settings.py changed, reloading.
django.utils.autoreload - INFO - /Users/elliott/Dropbox/pROJECTS/web_Dev/storevictor/storevictor/storevictor/settings.py changed, reloading.
django.utils.autoreload - INFO - /Users/elliott/Dropbox/pROJECTS/web_Dev/storevictor/storevictor/store/views.py changed, reloading.
django.utils.autoreload - INFO - /Users/elliott/Dropbox/pROJECTS/web_Dev/storevictor/storevictor/store/views.py changed, reloading.
django.utils.autoreload - INFO - /Users/elliott/Dropbox/pROJECTS/web_Dev/storevictor/storevictor/store/views.py changed, reloading.
django.utils.autoreload - INFO - /Users/elliott/Dropbox/pROJECTS/web_Dev/storevictor/storevictor/store/views.py changed, reloading.
django.utils.autoreload - INFO - /Users/elliott/Dropbox/pROJECTS/web_Dev/storevictor/storevictor/store/views.py changed, reloading.
django.utils.autoreload - INFO - /Users/elliott/Dropbox/pROJECTS/web_Dev/storevictor/storevictor/store/views.py changed, reloading.
django.utils.autoreload - INFO - /Users/elliott/Dropbox/pROJECTS/web_Dev/storevictor/storevictor/store/views.py changed, reloading.
django.utils.autoreload - INFO - /Users/elliott/Dropbox/pROJECTS/web_Dev/storevictor/storevictor/store/views.py changed, reloading.
django.utils.autoreload - INFO - /Users/elliott/Dropbox/pROJECTS/web_Dev/storevictor/storevictor/store/views.py changed, reloading.
django.utils.autoreload - INFO - /Users/elliott/Dropbox/pROJECTS/web_Dev/storevictor/storevictor/store/views.py changed, reloading.
django.utils.autoreload - INFO - /Users/elliott/Dropbox/pROJECTS/web_Dev/storevictor/storevictor/store/views.py changed, reloading.
django.utils.autoreload - INFO - /Users/elliott/Dropbox/pROJECTS/web_Dev/storevictor/storevictor/store/views.py changed, reloading.
django.utils.autoreload - INFO - /Users/elliott/Dropbox/pROJECTS/web_Dev/storevictor/storevictor/store/views.py changed, reloading.
django.utils.autoreload - INFO - /Users/elliott/Dropbox/pROJECTS/web_Dev/storevictor/storevictor/store/views.py changed, reloading.
django.utils.autoreload - INFO - /Users/elliott/Dropbox/pROJECTS/web_Dev/storevictor/storevictor/store/views.py changed, reloading.
django.utils.autoreload - INFO - /Users/elliott/Dropbox/pROJECTS/web_Dev/storevictor/storevictor/store/views.py changed, reloading.
django.request - ERROR - Internal Server Error: /v0.5/store/operations/chat/respond/
Traceback (most recent call last):
  File "/Users/elliott/python_venv/store/lib/python3.9/site-packages/django/db/backends/utils.py", line 84, in _execute
    return self.cursor.execute(sql, params)
  File "/Users/elliott/python_venv/store/lib/python3.9/site-packages/django/db/backends/sqlite3/base.py", line 423, in execute
    return Database.Cursor.execute(self, query, params)
sqlite3.OperationalError: database is locked

The above exception was the direct cause of the following exception:

Traceback (most recent call last):
  File "/Users/elliott/python_venv/store/lib/python3.9/site-packages/django/core/handlers/exception.py", line 47, in inner
    response = get_response(request)
  File "/Users/elliott/python_venv/store/lib/python3.9/site-packages/django/core/handlers/base.py", line 181, in _get_response
    response = wrapped_callback(request, *callback_args, **callback_kwargs)
  File "/Users/elliott/python_venv/store/lib/python3.9/site-packages/django/views/decorators/csrf.py", line 54, in wrapped_view
    return view_func(*args, **kwargs)
  File "/Users/elliott/python_venv/store/lib/python3.9/site-packages/django/views/generic/base.py", line 70, in view
    return self.dispatch(request, *args, **kwargs)
  File "/Users/elliott/python_venv/store/lib/python3.9/site-packages/rest_framework/views.py", line 509, in dispatch
    response = self.handle_exception(exc)
  File "/Users/elliott/python_venv/store/lib/python3.9/site-packages/rest_framework/views.py", line 469, in handle_exception
    self.raise_uncaught_exception(exc)
  File "/Users/elliott/python_venv/store/lib/python3.9/site-packages/rest_framework/views.py", line 480, in raise_uncaught_exception
    raise exc
  File "/Users/elliott/python_venv/store/lib/python3.9/site-packages/rest_framework/views.py", line 506, in dispatch
    response = handler(request, *args, **kwargs)
  File "/Users/elliott/Dropbox/pROJECTS/web_Dev/storevictor/storevictor/store/views.py", line 50, in post
    serializer.save()
  File "/Users/elliott/python_venv/store/lib/python3.9/site-packages/rest_framework/serializers.py", line 205, in save
    self.instance = self.create(validated_data)
  File "/Users/elliott/python_venv/store/lib/python3.9/site-packages/rest_framework/serializers.py", line 939, in create
    instance = ModelClass._default_manager.create(**validated_data)
  File "/Users/elliott/python_venv/store/lib/python3.9/site-packages/django/db/models/manager.py", line 85, in manager_method
    return getattr(self.get_queryset(), name)(*args, **kwargs)
  File "/Users/elliott/python_venv/store/lib/python3.9/site-packages/django/db/models/query.py", line 453, in create
    obj.save(force_insert=True, using=self.db)
  File "/Users/elliott/python_venv/store/lib/python3.9/site-packages/django/db/models/base.py", line 726, in save
    self.save_base(using=using, force_insert=force_insert,
  File "/Users/elliott/python_venv/store/lib/python3.9/site-packages/django/db/models/base.py", line 763, in save_base
    updated = self._save_table(
  File "/Users/elliott/python_venv/store/lib/python3.9/site-packages/django/db/models/base.py", line 868, in _save_table
    results = self._do_insert(cls._base_manager, using, fields, returning_fields, raw)
  File "/Users/elliott/python_venv/store/lib/python3.9/site-packages/django/db/models/base.py", line 906, in _do_insert
    return manager._insert(
  File "/Users/elliott/python_venv/store/lib/python3.9/site-packages/django/db/models/manager.py", line 85, in manager_method
    return getattr(self.get_queryset(), name)(*args, **kwargs)
  File "/Users/elliott/python_venv/store/lib/python3.9/site-packages/django/db/models/query.py", line 1270, in _insert
    return query.get_compiler(using=using).execute_sql(returning_fields)
  File "/Users/elliott/python_venv/store/lib/python3.9/site-packages/django/db/models/sql/compiler.py", line 1416, in execute_sql
    cursor.execute(sql, params)
  File "/Users/elliott/python_venv/store/lib/python3.9/site-packages/django/db/backends/utils.py", line 98, in execute
    return super().execute(sql, params)
  File "/Users/elliott/python_venv/store/lib/python3.9/site-packages/django/db/backends/utils.py", line 66, in execute
    return self._execute_with_wrappers(sql, params, many=False, executor=self._execute)
  File "/Users/elliott/python_venv/store/lib/python3.9/site-packages/django/db/backends/utils.py", line 75, in _execute_with_wrappers
    return executor(sql, params, many, context)
  File "/Users/elliott/python_venv/store/lib/python3.9/site-packages/django/db/backends/utils.py", line 84, in _execute
    return self.cursor.execute(sql, params)
  File "/Users/elliott/python_venv/store/lib/python3.9/site-packages/django/db/utils.py", line 90, in __exit__
    raise dj_exc_value.with_traceback(traceback) from exc_value
  File "/Users/elliott/python_venv/store/lib/python3.9/site-packages/django/db/backends/utils.py", line 84, in _execute
    return self.cursor.execute(sql, params)
  File "/Users/elliott/python_venv/store/lib/python3.9/site-packages/django/db/backends/sqlite3/base.py", line 423, in execute
    return Database.Cursor.execute(self, query, params)
django.db.utils.OperationalError: database is locked
django.request - ERROR - Internal Server Error: /v0.5/store/operations/chat/respond/
Traceback (most recent call last):
  File "/Users/elliott/python_venv/store/lib/python3.9/site-packages/django/db/backends/utils.py", line 84, in _execute
    return self.cursor.execute(sql, params)
  File "/Users/elliott/python_venv/store/lib/python3.9/site-packages/django/db/backends/sqlite3/base.py", line 423, in execute
    return Database.Cursor.execute(self, query, params)
sqlite3.OperationalError: database is locked

The above exception was the direct cause of the following exception:

Traceback (most recent call last):
  File "/Users/elliott/python_venv/store/lib/python3.9/site-packages/django/core/handlers/exception.py", line 47, in inner
    response = get_response(request)
  File "/Users/elliott/python_venv/store/lib/python3.9/site-packages/django/core/handlers/base.py", line 181, in _get_response
    response = wrapped_callback(request, *callback_args, **callback_kwargs)
  File "/Users/elliott/python_venv/store/lib/python3.9/site-packages/django/views/decorators/csrf.py", line 54, in wrapped_view
    return view_func(*args, **kwargs)
  File "/Users/elliott/python_venv/store/lib/python3.9/site-packages/django/views/generic/base.py", line 70, in view
    return self.dispatch(request, *args, **kwargs)
  File "/Users/elliott/python_venv/store/lib/python3.9/site-packages/rest_framework/views.py", line 509, in dispatch
    response = self.handle_exception(exc)
  File "/Users/elliott/python_venv/store/lib/python3.9/site-packages/rest_framework/views.py", line 469, in handle_exception
    self.raise_uncaught_exception(exc)
  File "/Users/elliott/python_venv/store/lib/python3.9/site-packages/rest_framework/views.py", line 480, in raise_uncaught_exception
    raise exc
  File "/Users/elliott/python_venv/store/lib/python3.9/site-packages/rest_framework/views.py", line 506, in dispatch
    response = handler(request, *args, **kwargs)
  File "/Users/elliott/Dropbox/pROJECTS/web_Dev/storevictor/storevictor/store/views.py", line 50, in post
    serializer.save()
  File "/Users/elliott/python_venv/store/lib/python3.9/site-packages/rest_framework/serializers.py", line 205, in save
    self.instance = self.create(validated_data)
  File "/Users/elliott/python_venv/store/lib/python3.9/site-packages/rest_framework/serializers.py", line 939, in create
    instance = ModelClass._default_manager.create(**validated_data)
  File "/Users/elliott/python_venv/store/lib/python3.9/site-packages/django/db/models/manager.py", line 85, in manager_method
    return getattr(self.get_queryset(), name)(*args, **kwargs)
  File "/Users/elliott/python_venv/store/lib/python3.9/site-packages/django/db/models/query.py", line 453, in create
    obj.save(force_insert=True, using=self.db)
  File "/Users/elliott/python_venv/store/lib/python3.9/site-packages/django/db/models/base.py", line 726, in save
    self.save_base(using=using, force_insert=force_insert,
  File "/Users/elliott/python_venv/store/lib/python3.9/site-packages/django/db/models/base.py", line 763, in save_base
    updated = self._save_table(
  File "/Users/elliott/python_venv/store/lib/python3.9/site-packages/django/db/models/base.py", line 868, in _save_table
    results = self._do_insert(cls._base_manager, using, fields, returning_fields, raw)
  File "/Users/elliott/python_venv/store/lib/python3.9/site-packages/django/db/models/base.py", line 906, in _do_insert
    return manager._insert(
  File "/Users/elliott/python_venv/store/lib/python3.9/site-packages/django/db/models/manager.py", line 85, in manager_method
    return getattr(self.get_queryset(), name)(*args, **kwargs)
  File "/Users/elliott/python_venv/store/lib/python3.9/site-packages/django/db/models/query.py", line 1270, in _insert
    return query.get_compiler(using=using).execute_sql(returning_fields)
  File "/Users/elliott/python_venv/store/lib/python3.9/site-packages/django/db/models/sql/compiler.py", line 1416, in execute_sql
    cursor.execute(sql, params)
  File "/Users/elliott/python_venv/store/lib/python3.9/site-packages/django/db/backends/utils.py", line 98, in execute
    return super().execute(sql, params)
  File "/Users/elliott/python_venv/store/lib/python3.9/site-packages/django/db/backends/utils.py", line 66, in execute
    return self._execute_with_wrappers(sql, params, many=False, executor=self._execute)
  File "/Users/elliott/python_venv/store/lib/python3.9/site-packages/django/db/backends/utils.py", line 75, in _execute_with_wrappers
    return executor(sql, params, many, context)
  File "/Users/elliott/python_venv/store/lib/python3.9/site-packages/django/db/backends/utils.py", line 84, in _execute
    return self.cursor.execute(sql, params)
  File "/Users/elliott/python_venv/store/lib/python3.9/site-packages/django/db/utils.py", line 90, in __exit__
    raise dj_exc_value.with_traceback(traceback) from exc_value
  File "/Users/elliott/python_venv/store/lib/python3.9/site-packages/django/db/backends/utils.py", line 84, in _execute
    return self.cursor.execute(sql, params)
  File "/Users/elliott/python_venv/store/lib/python3.9/site-packages/django/db/backends/sqlite3/base.py", line 423, in execute
    return Database.Cursor.execute(self, query, params)
django.db.utils.OperationalError: database is locked
django.utils.autoreload - INFO - /Users/elliott/Dropbox/pROJECTS/web_Dev/storevictor/storevictor/store/serializers.py changed, reloading.
django.utils.autoreload - INFO - /Users/elliott/Dropbox/pROJECTS/web_Dev/storevictor/storevictor/store/views.py changed, reloading.
django.request - ERROR - Internal Server Error: /v0.5/store/operations/chat/respond/
Traceback (most recent call last):
  File "/Users/elliott/python_venv/store/lib/python3.9/site-packages/django/db/backends/utils.py", line 84, in _execute
    return self.cursor.execute(sql, params)
  File "/Users/elliott/python_venv/store/lib/python3.9/site-packages/django/db/backends/sqlite3/base.py", line 423, in execute
    return Database.Cursor.execute(self, query, params)
sqlite3.OperationalError: database is locked

The above exception was the direct cause of the following exception:

Traceback (most recent call last):
  File "/Users/elliott/python_venv/store/lib/python3.9/site-packages/django/core/handlers/exception.py", line 47, in inner
    response = get_response(request)
  File "/Users/elliott/python_venv/store/lib/python3.9/site-packages/django/core/handlers/base.py", line 181, in _get_response
    response = wrapped_callback(request, *callback_args, **callback_kwargs)
  File "/Users/elliott/python_venv/store/lib/python3.9/site-packages/django/views/decorators/csrf.py", line 54, in wrapped_view
    return view_func(*args, **kwargs)
  File "/Users/elliott/python_venv/store/lib/python3.9/site-packages/django/views/generic/base.py", line 70, in view
    return self.dispatch(request, *args, **kwargs)
  File "/Users/elliott/python_venv/store/lib/python3.9/site-packages/rest_framework/views.py", line 509, in dispatch
    response = self.handle_exception(exc)
  File "/Users/elliott/python_venv/store/lib/python3.9/site-packages/rest_framework/views.py", line 469, in handle_exception
    self.raise_uncaught_exception(exc)
  File "/Users/elliott/python_venv/store/lib/python3.9/site-packages/rest_framework/views.py", line 480, in raise_uncaught_exception
    raise exc
  File "/Users/elliott/python_venv/store/lib/python3.9/site-packages/rest_framework/views.py", line 506, in dispatch
    response = handler(request, *args, **kwargs)
  File "/Users/elliott/Dropbox/pROJECTS/web_Dev/storevictor/storevictor/store/views.py", line 51, in post
    serializer.save()
  File "/Users/elliott/python_venv/store/lib/python3.9/site-packages/rest_framework/serializers.py", line 205, in save
    self.instance = self.create(validated_data)
  File "/Users/elliott/python_venv/store/lib/python3.9/site-packages/rest_framework/serializers.py", line 939, in create
    instance = ModelClass._default_manager.create(**validated_data)
  File "/Users/elliott/python_venv/store/lib/python3.9/site-packages/django/db/models/manager.py", line 85, in manager_method
    return getattr(self.get_queryset(), name)(*args, **kwargs)
  File "/Users/elliott/python_venv/store/lib/python3.9/site-packages/django/db/models/query.py", line 453, in create
    obj.save(force_insert=True, using=self.db)
  File "/Users/elliott/python_venv/store/lib/python3.9/site-packages/django/db/models/base.py", line 726, in save
    self.save_base(using=using, force_insert=force_insert,
  File "/Users/elliott/python_venv/store/lib/python3.9/site-packages/django/db/models/base.py", line 763, in save_base
    updated = self._save_table(
  File "/Users/elliott/python_venv/store/lib/python3.9/site-packages/django/db/models/base.py", line 868, in _save_table
    results = self._do_insert(cls._base_manager, using, fields, returning_fields, raw)
  File "/Users/elliott/python_venv/store/lib/python3.9/site-packages/django/db/models/base.py", line 906, in _do_insert
    return manager._insert(
  File "/Users/elliott/python_venv/store/lib/python3.9/site-packages/django/db/models/manager.py", line 85, in manager_method
    return getattr(self.get_queryset(), name)(*args, **kwargs)
  File "/Users/elliott/python_venv/store/lib/python3.9/site-packages/django/db/models/query.py", line 1270, in _insert
    return query.get_compiler(using=using).execute_sql(returning_fields)
  File "/Users/elliott/python_venv/store/lib/python3.9/site-packages/django/db/models/sql/compiler.py", line 1416, in execute_sql
    cursor.execute(sql, params)
  File "/Users/elliott/python_venv/store/lib/python3.9/site-packages/django/db/backends/utils.py", line 98, in execute
    return super().execute(sql, params)
  File "/Users/elliott/python_venv/store/lib/python3.9/site-packages/django/db/backends/utils.py", line 66, in execute
    return self._execute_with_wrappers(sql, params, many=False, executor=self._execute)
  File "/Users/elliott/python_venv/store/lib/python3.9/site-packages/django/db/backends/utils.py", line 75, in _execute_with_wrappers
    return executor(sql, params, many, context)
  File "/Users/elliott/python_venv/store/lib/python3.9/site-packages/django/db/backends/utils.py", line 84, in _execute
    return self.cursor.execute(sql, params)
  File "/Users/elliott/python_venv/store/lib/python3.9/site-packages/django/db/utils.py", line 90, in __exit__
    raise dj_exc_value.with_traceback(traceback) from exc_value
  File "/Users/elliott/python_venv/store/lib/python3.9/site-packages/django/db/backends/utils.py", line 84, in _execute
    return self.cursor.execute(sql, params)
  File "/Users/elliott/python_venv/store/lib/python3.9/site-packages/django/db/backends/sqlite3/base.py", line 423, in execute
    return Database.Cursor.execute(self, query, params)
django.db.utils.OperationalError: database is locked
django.request - ERROR - Internal Server Error: /v0.5/store/operations/chat/respond/
Traceback (most recent call last):
  File "/Users/elliott/python_venv/store/lib/python3.9/site-packages/django/core/handlers/exception.py", line 47, in inner
    response = get_response(request)
  File "/Users/elliott/python_venv/store/lib/python3.9/site-packages/django/core/handlers/base.py", line 181, in _get_response
    response = wrapped_callback(request, *callback_args, **callback_kwargs)
  File "/Users/elliott/python_venv/store/lib/python3.9/site-packages/django/views/decorators/csrf.py", line 54, in wrapped_view
    return view_func(*args, **kwargs)
  File "/Users/elliott/python_venv/store/lib/python3.9/site-packages/django/views/generic/base.py", line 70, in view
    return self.dispatch(request, *args, **kwargs)
  File "/Users/elliott/python_venv/store/lib/python3.9/site-packages/rest_framework/views.py", line 509, in dispatch
    response = self.handle_exception(exc)
  File "/Users/elliott/python_venv/store/lib/python3.9/site-packages/rest_framework/views.py", line 469, in handle_exception
    self.raise_uncaught_exception(exc)
  File "/Users/elliott/python_venv/store/lib/python3.9/site-packages/rest_framework/views.py", line 480, in raise_uncaught_exception
    raise exc
  File "/Users/elliott/python_venv/store/lib/python3.9/site-packages/rest_framework/views.py", line 506, in dispatch
    response = handler(request, *args, **kwargs)
  File "/Users/elliott/Dropbox/pROJECTS/web_Dev/storevictor/storevictor/store/views.py", line 58, in post
    operator_first_name = operator.user.user.first_name
AttributeError: 'User' object has no attribute 'user'
django.utils.autoreload - INFO - /Users/elliott/Dropbox/pROJECTS/web_Dev/storevictor/storevictor/store/views.py changed, reloading.
django.utils.autoreload - INFO - /Users/elliott/Dropbox/pROJECTS/web_Dev/storevictor/storevictor/store/views.py changed, reloading.
django.utils.autoreload - INFO - /Users/elliott/Dropbox/pROJECTS/web_Dev/storevictor/storevictor/store/views.py changed, reloading.
django.utils.autoreload - INFO - /Users/elliott/Dropbox/pROJECTS/web_Dev/storevictor/storevictor/store/views.py changed, reloading.
django.utils.autoreload - INFO - /Users/elliott/Dropbox/pROJECTS/web_Dev/storevictor/storevictor/store/models.py changed, reloading.
django.utils.autoreload - INFO - /Users/elliott/Dropbox/pROJECTS/web_Dev/storevictor/storevictor/store/models.py changed, reloading.
django.utils.autoreload - INFO - /Users/elliott/Dropbox/pROJECTS/web_Dev/storevictor/storevictor/store/admin.py changed, reloading.
django.utils.autoreload - INFO - /Users/elliott/Dropbox/pROJECTS/web_Dev/storevictor/storevictor/store/models.py changed, reloading.
django.request - ERROR - Internal Server Error: /admin/store/discount/add/
Traceback (most recent call last):
  File "/Users/elliott/python_venv/store/lib/python3.9/site-packages/django/core/handlers/exception.py", line 47, in inner
    response = get_response(request)
  File "/Users/elliott/python_venv/store/lib/python3.9/site-packages/django/core/handlers/base.py", line 181, in _get_response
    response = wrapped_callback(request, *callback_args, **callback_kwargs)
  File "/Users/elliott/python_venv/store/lib/python3.9/site-packages/django/contrib/admin/options.py", line 616, in wrapper
    return self.admin_site.admin_view(view)(*args, **kwargs)
  File "/Users/elliott/python_venv/store/lib/python3.9/site-packages/django/utils/decorators.py", line 130, in _wrapped_view
    response = view_func(request, *args, **kwargs)
  File "/Users/elliott/python_venv/store/lib/python3.9/site-packages/django/views/decorators/cache.py", line 44, in _wrapped_view_func
    response = view_func(request, *args, **kwargs)
  File "/Users/elliott/python_venv/store/lib/python3.9/site-packages/django/contrib/admin/sites.py", line 232, in inner
    return view(request, *args, **kwargs)
  File "/Users/elliott/python_venv/store/lib/python3.9/site-packages/django/contrib/admin/options.py", line 1657, in add_view
    return self.changeform_view(request, None, form_url, extra_context)
  File "/Users/elliott/python_venv/store/lib/python3.9/site-packages/django/utils/decorators.py", line 43, in _wrapper
    return bound_method(*args, **kwargs)
  File "/Users/elliott/python_venv/store/lib/python3.9/site-packages/django/utils/decorators.py", line 130, in _wrapped_view
    response = view_func(request, *args, **kwargs)
  File "/Users/elliott/python_venv/store/lib/python3.9/site-packages/django/contrib/admin/options.py", line 1540, in changeform_view
    return self._changeform_view(request, object_id, form_url, extra_context)
  File "/Users/elliott/python_venv/store/lib/python3.9/site-packages/django/contrib/admin/options.py", line 1590, in _changeform_view
    self.log_addition(request, new_object, change_message)
  File "/Users/elliott/python_venv/store/lib/python3.9/site-packages/django/contrib/admin/options.py", line 815, in log_addition
    object_repr=str(object),
  File "/Users/elliott/Dropbox/pROJECTS/web_Dev/storevictor/storevictor/store/models.py", line 34, in __str__
    return '{}-{}'.format(self.name, self.timezone)
AttributeError: 'Discount' object has no attribute 'name'
django.utils.autoreload - INFO - /Users/elliott/Dropbox/pROJECTS/web_Dev/storevictor/storevictor/store/models.py changed, reloading.
django.utils.autoreload - INFO - /Users/elliott/Dropbox/pROJECTS/web_Dev/storevictor/storevictor/store/models.py changed, reloading.
django.utils.autoreload - INFO - /Users/elliott/Dropbox/pROJECTS/web_Dev/storevictor/storevictor/store/views.py changed, reloading.
django.utils.autoreload - INFO - /Users/elliott/Dropbox/pROJECTS/web_Dev/storevictor/storevictor/store/views.py changed, reloading.
django.utils.autoreload - INFO - /Users/elliott/Dropbox/pROJECTS/web_Dev/storevictor/storevictor/store/views.py changed, reloading.
django.utils.autoreload - INFO - /Users/elliott/Dropbox/pROJECTS/web_Dev/storevictor/storevictor/store/views.py changed, reloading.
django.utils.autoreload - INFO - /Users/elliott/Dropbox/pROJECTS/web_Dev/storevictor/storevictor/store/models.py changed, reloading.
django.utils.autoreload - INFO - /Users/elliott/Dropbox/pROJECTS/web_Dev/storevictor/storevictor/store/views.py changed, reloading.
django.utils.autoreload - INFO - /Users/elliott/Dropbox/pROJECTS/web_Dev/storevictor/storevictor/store/views.py changed, reloading.
django.request - ERROR - Internal Server Error: /v0.5/store/operations/chat/respond/
Traceback (most recent call last):
  File "/Users/elliott/python_venv/store/lib/python3.9/site-packages/django/core/handlers/exception.py", line 47, in inner
    response = get_response(request)
  File "/Users/elliott/python_venv/store/lib/python3.9/site-packages/django/core/handlers/base.py", line 181, in _get_response
    response = wrapped_callback(request, *callback_args, **callback_kwargs)
  File "/Users/elliott/python_venv/store/lib/python3.9/site-packages/django/views/decorators/csrf.py", line 54, in wrapped_view
    return view_func(*args, **kwargs)
  File "/Users/elliott/python_venv/store/lib/python3.9/site-packages/django/views/generic/base.py", line 70, in view
    return self.dispatch(request, *args, **kwargs)
  File "/Users/elliott/python_venv/store/lib/python3.9/site-packages/rest_framework/views.py", line 509, in dispatch
    response = self.handle_exception(exc)
  File "/Users/elliott/python_venv/store/lib/python3.9/site-packages/rest_framework/views.py", line 469, in handle_exception
    self.raise_uncaught_exception(exc)
  File "/Users/elliott/python_venv/store/lib/python3.9/site-packages/rest_framework/views.py", line 480, in raise_uncaught_exception
    raise exc
  File "/Users/elliott/python_venv/store/lib/python3.9/site-packages/rest_framework/views.py", line 506, in dispatch
    response = handler(request, *args, **kwargs)
  File "/Users/elliott/Dropbox/pROJECTS/web_Dev/storevictor/storevictor/store/views.py", line 63, in post
    discount_code = JD20
NameError: name 'JD20' is not defined
django.utils.autoreload - INFO - /Users/elliott/Dropbox/pROJECTS/web_Dev/storevictor/storevictor/store/views.py changed, reloading.
django.utils.autoreload - INFO - /Users/elliott/Dropbox/pROJECTS/web_Dev/storevictor/storevictor/store/views.py changed, reloading.
django.utils.autoreload - INFO - /Users/elliott/Dropbox/pROJECTS/web_Dev/storevictor/storevictor/store/views.py changed, reloading.
django.utils.autoreload - INFO - /Users/elliott/Dropbox/pROJECTS/web_Dev/storevictor/storevictor/store/serializers.py changed, reloading.
django.utils.autoreload - INFO - /Users/elliott/Dropbox/pROJECTS/web_Dev/storevictor/storevictor/store/serializers.py changed, reloading.
django.utils.autoreload - INFO - /Users/elliott/Dropbox/pROJECTS/web_Dev/storevictor/storevictor/store/serializers.py changed, reloading.
django.utils.autoreload - INFO - /Users/elliott/Dropbox/pROJECTS/web_Dev/storevictor/storevictor/store/views.py changed, reloading.
django.utils.autoreload - INFO - /Users/elliott/Dropbox/pROJECTS/web_Dev/storevictor/storevictor/store/views.py changed, reloading.
django.utils.autoreload - INFO - /Users/elliott/Dropbox/pROJECTS/web_Dev/storevictor/storevictor/store/views.py changed, reloading.
django.utils.autoreload - INFO - /Users/elliott/Dropbox/pROJECTS/web_Dev/storevictor/storevictor/store/views.py changed, reloading.
django.utils.autoreload - INFO - /Users/elliott/Dropbox/pROJECTS/web_Dev/storevictor/storevictor/store/views.py changed, reloading.
django.utils.autoreload - INFO - /Users/elliott/Dropbox/pROJECTS/web_Dev/storevictor/storevictor/store/views.py changed, reloading.
django.utils.autoreload - INFO - /Users/elliott/Dropbox/pROJECTS/web_Dev/storevictor/storevictor/store/views.py changed, reloading.
django.utils.autoreload - INFO - /Users/elliott/Dropbox/pROJECTS/web_Dev/storevictor/storevictor/store/views.py changed, reloading.
django.utils.autoreload - INFO - /Users/elliott/Dropbox/pROJECTS/web_Dev/storevictor/storevictor/store/views.py changed, reloading.
django.utils.autoreload - INFO - /Users/elliott/Dropbox/pROJECTS/web_Dev/storevictor/storevictor/store/views.py changed, reloading.
django.request - ERROR - Internal Server Error: /v0.5/store/operations/chat/respond/
Traceback (most recent call last):
  File "/Users/elliott/python_venv/store/lib/python3.9/site-packages/django/core/handlers/exception.py", line 47, in inner
    response = get_response(request)
  File "/Users/elliott/python_venv/store/lib/python3.9/site-packages/django/core/handlers/base.py", line 181, in _get_response
    response = wrapped_callback(request, *callback_args, **callback_kwargs)
  File "/Users/elliott/python_venv/store/lib/python3.9/site-packages/django/views/decorators/csrf.py", line 54, in wrapped_view
    return view_func(*args, **kwargs)
  File "/Users/elliott/python_venv/store/lib/python3.9/site-packages/django/views/generic/base.py", line 70, in view
    return self.dispatch(request, *args, **kwargs)
  File "/Users/elliott/python_venv/store/lib/python3.9/site-packages/rest_framework/views.py", line 509, in dispatch
    response = self.handle_exception(exc)
  File "/Users/elliott/python_venv/store/lib/python3.9/site-packages/rest_framework/views.py", line 469, in handle_exception
    self.raise_uncaught_exception(exc)
  File "/Users/elliott/python_venv/store/lib/python3.9/site-packages/rest_framework/views.py", line 480, in raise_uncaught_exception
    raise exc
  File "/Users/elliott/python_venv/store/lib/python3.9/site-packages/rest_framework/views.py", line 506, in dispatch
    response = handler(request, *args, **kwargs)
  File "/Users/elliott/Dropbox/pROJECTS/web_Dev/storevictor/storevictor/store/views.py", line 68, in post
    notification(
  File "/Users/elliott/Dropbox/pROJECTS/web_Dev/storevictor/storevictor/store/views.py", line 28, in notification
    operator_first_name % (discount_code),
TypeError: not all arguments converted during string formatting
django.utils.autoreload - INFO - /Users/elliott/Dropbox/pROJECTS/web_Dev/storevictor/storevictor/store/views.py changed, reloading.
django.request - ERROR - Internal Server Error: /v0.5/store/operations/chat/respond/
Traceback (most recent call last):
  File "/Users/elliott/python_venv/store/lib/python3.9/site-packages/django/core/handlers/exception.py", line 47, in inner
    response = get_response(request)
  File "/Users/elliott/python_venv/store/lib/python3.9/site-packages/django/core/handlers/base.py", line 181, in _get_response
    response = wrapped_callback(request, *callback_args, **callback_kwargs)
  File "/Users/elliott/python_venv/store/lib/python3.9/site-packages/django/views/decorators/csrf.py", line 54, in wrapped_view
    return view_func(*args, **kwargs)
  File "/Users/elliott/python_venv/store/lib/python3.9/site-packages/django/views/generic/base.py", line 70, in view
    return self.dispatch(request, *args, **kwargs)
  File "/Users/elliott/python_venv/store/lib/python3.9/site-packages/rest_framework/views.py", line 509, in dispatch
    response = self.handle_exception(exc)
  File "/Users/elliott/python_venv/store/lib/python3.9/site-packages/rest_framework/views.py", line 469, in handle_exception
    self.raise_uncaught_exception(exc)
  File "/Users/elliott/python_venv/store/lib/python3.9/site-packages/rest_framework/views.py", line 480, in raise_uncaught_exception
    raise exc
  File "/Users/elliott/python_venv/store/lib/python3.9/site-packages/rest_framework/views.py", line 506, in dispatch
    response = handler(request, *args, **kwargs)
  File "/Users/elliott/Dropbox/pROJECTS/web_Dev/storevictor/storevictor/store/views.py", line 68, in post
    notification(
  File "/Users/elliott/Dropbox/pROJECTS/web_Dev/storevictor/storevictor/store/views.py", line 28, in notification
    operator_first_name% (discount_code),
TypeError: not all arguments converted during string formatting
django.utils.autoreload - INFO - /Users/elliott/Dropbox/pROJECTS/web_Dev/storevictor/storevictor/store/views.py changed, reloading.
django.utils.autoreload - INFO - /Users/elliott/Dropbox/pROJECTS/web_Dev/storevictor/storevictor/store/views.py changed, reloading.
django.utils.autoreload - INFO - /Users/elliott/Dropbox/pROJECTS/web_Dev/storevictor/storevictor/store/views.py changed, reloading.
django.utils.autoreload - INFO - /Users/elliott/Dropbox/pROJECTS/web_Dev/storevictor/storevictor/store/views.py changed, reloading.
django.utils.autoreload - INFO - /Users/elliott/Dropbox/pROJECTS/web_Dev/storevictor/storevictor/store/views.py changed, reloading.
django.utils.autoreload - INFO - /Users/elliott/Dropbox/pROJECTS/web_Dev/storevictor/storevictor/store/views.py changed, reloading.
django.utils.autoreload - INFO - /Users/elliott/Dropbox/pROJECTS/web_Dev/storevictor/storevictor/store/views.py changed, reloading.
django.utils.autoreload - INFO - /Users/elliott/Dropbox/pROJECTS/web_Dev/storevictor/storevictor/store/views.py changed, reloading.
django.utils.autoreload - INFO - /Users/elliott/Dropbox/pROJECTS/web_Dev/storevictor/storevictor/store/views.py changed, reloading.
django.utils.autoreload - INFO - /Users/elliott/Dropbox/pROJECTS/web_Dev/storevictor/storevictor/store/views.py changed, reloading.
django.utils.autoreload - INFO - /Users/elliott/Dropbox/pROJECTS/web_Dev/storevictor/storevictor/store/views.py changed, reloading.
django.utils.autoreload - INFO - /Users/elliott/Dropbox/pROJECTS/web_Dev/storevictor/storevictor/storevictor/urls.py changed, reloading.
